<?xml version="1.0"?>
<robot name="quadruped_robot">

    <!-- 로봇의 베이스 링크 -->
    <link name="base_link">
        <inertial>
            <origin xyz="0 0 0" />
            <mass value="1.0" />
            <inertia ixx="0.1" ixy="0" ixz="0" iyy="0.1" iyz="0" izz="0.1" />
        </inertial>
        <visual>
            <origin xyz="0 0 0" rpy="0 0 0" />
            <geometry>
                <box size="0.15 0.15 0.1" />
            </geometry>
            <material name="blue">
                <color rgba="0 0 1 1" />
            </material>
        </visual>
        <collision>
            <origin xyz="0 0 0" rpy="0 0 0" />
            <geometry>
                <box size="0.3 0.3 0.1" />
            </geometry>
        </collision>
    </link>

    <!-- 첫 번째 다리 링크 (힙) -->
    <link name="hip_link">
        <inertial>
            <origin xyz="0 0 0" />
            <mass value="0.5" />
            <inertia ixx="0.05" ixy="0" ixz="0" iyy="0.05" iyz="0" izz="0.05" />
        </inertial>
        <visual>
            <origin xyz="0 0 -0.15" rpy="0 0 0" />
            <geometry>
                <cylinder length="0.3" radius="0.03" />
            </geometry>
            <material name="green">
                <color rgba="0 1 0 1" />
            </material>
        </visual>
        <collision>
            <origin xyz="0 0 -0.15" rpy="0 0 0" />
            <geometry>
                <cylinder length="0.3" radius="0.03" />
            </geometry>
        </collision>
    </link>

    <!-- 두 번째 다리 링크 (무릎) -->
    <link name="knee_link">
        <inertial>
            <origin xyz="0 0 0" />
            <mass value="0.3" />
            <inertia ixx="0.03" ixy="0" ixz="0" iyy="0.03" iyz="0" izz="0.03" />
        </inertial>
        <visual>
            <origin xyz="0 0 -0.15" rpy="0 0 0" />
            <geometry>
                <cylinder length="0.3" radius="0.03" />
            </geometry>
            <material name="red">
                <color rgba="1 0 0 1" />
            </material>
        </visual>
        <collision>
            <origin xyz="0 0 -0.3" rpy="0 0 0" />
            <geometry>
                <cylinder length="0.05" radius="0.04" /> <!-- 확대된 충돌 영역 -->
            </geometry>
        </collision>
    </link>

    <!-- 첫 번째 관절 (힙) -->
    <joint name="hip_joint" type="revolute">
        <parent link="base_link" />
        <child link="hip_link" />
        <origin xyz="0 0 0" rpy="0 0 0" />
        <axis xyz="0 1 0" />
        <limit effort="1.0" velocity="1.0" lower="-3.14" upper="3.14" />
    </joint>

    <!-- 두 번째 관절 (무릎) -->
    <joint name="knee_joint" type="revolute">
        <parent link="hip_link" />
        <child link="knee_link" />
        <origin xyz="0 0 -0.3" rpy="0 0 0" />
        <axis xyz="0 1 0" />
        <limit effort="1.0" velocity="1.0" lower="-3.14" upper="3.14" />
    </joint>

</robot>
