<?xml version="1.0"?>
<robot name="quadruped_robot">

    <!-- Base Link -->
    <link name="base_link">
        <inertial>
            <origin xyz="0 0 0" />
            <mass value="3.0" /> <!-- 질량을 조금 증가 -->
            <inertia ixx="0.15" ixy="0" ixz="0" iyy="0.15" iyz="0" izz="0.1" /> <!-- 관성값 조정 -->
        </inertial>
        <visual>
            <origin xyz="0 0 0" rpy="0 0 0" />
            <geometry>
                <box size="0.4 0.2 0.1" />
            </geometry>
            <material name="blue">
                <color rgba="0 0 1 1" />
            </material>
        </visual>
        <collision>
            <origin xyz="0 0 0" rpy="0 0 0" />
            <geometry>
                <box size="0.3 0.3 0.1" />
            </geometry>
        </collision>
    </link>

    <!-- Front Left Leg -->
    <link name="front_left_abad_link">
        <inertial>
            <origin xyz="0 0 0" />
            <mass value="0.5" /> <!-- 다리 링크 질량 증가 -->
            <inertia ixx="0.02" ixy="0" ixz="0" iyy="0.02" iyz="0" izz="0.01" /> <!-- 적절한 관성 조정 -->
        </inertial>
        <visual>
            <origin xyz="0 0 0" rpy="1.5708 0 1.5708" />
            <geometry>
                <cylinder length="0.05" radius="0.02" />
            </geometry>
            <material name="yellow">
                <color rgba="1 1 0 1" />
            </material>
        </visual>
    </link>
    <joint name="front_left_abad_joint" type="revolute">
        <parent link="base_link" />
        <child link="front_left_abad_link" />
        <origin xyz="0.15 0.1 0" rpy="0 0 0" />
        <axis xyz="1 0 0" />
        <limit effort="1.0" velocity="1.0" lower="-1.5" upper="1.5" />
    </joint>
    <link name="front_left_hip_link">
        <inertial>
            <origin xyz="0 0 -0.1" /> <!-- 질량 중심을 다리 쪽으로 이동 -->
            <mass value="0.7" /> <!-- 다리 질량 증가 -->
            <inertia ixx="0.03" ixy="0" ixz="0" iyy="0.03" iyz="0" izz="0.02" /> <!-- 관성값 조정 -->
        </inertial>
        <visual>
            <origin xyz="0 0.02 -0.1" rpy="0 0 0" />
            <geometry>
                <cylinder length="0.2" radius="0.03" />
            </geometry>
            <material name="green">
                <color rgba="0 1 0 1" />
            </material>
        </visual>
        <collision>
            <origin xyz="0 0.02 -0.1" rpy="0 0 0" />
            <geometry>
                <cylinder length="0.2" radius="0.03" />
            </geometry>
        </collision>
    </link>
    <joint name="front_left_hip_joint" type="revolute">
        <parent link="front_left_abad_link" />
        <child link="front_left_hip_link" />
        <origin xyz="0 0.02 0" rpy="0 0 0" />
        <axis xyz="0 1 0" />
        <limit effort="1.0" velocity="1.0" lower="-3.14" upper="3.14" />
    </joint>
    <link name="front_left_knee_link">
        <inertial>
            <origin xyz="0 0 -0.1" />
            <mass value="0.4" /> <!-- 무릎 링크 질량 증가 -->
            <inertia ixx="0.02" ixy="0" ixz="0" iyy="0.02" iyz="0" izz="0.01" /> <!-- 관성값 조정 -->
        </inertial>
        <visual>
            <origin xyz="0 0.02 -0.1" rpy="0 0 0" />
            <geometry>
                <cylinder length="0.2" radius="0.03" />
            </geometry>
            <material name="red">
                <color rgba="1 0 0 1" />
            </material>
        </visual>
        <collision>
            <origin xyz="0 0.02 -0.1" rpy="0 0 0" />
            <geometry>
                <cylinder length="0.2" radius="0.03" />
            </geometry>
        </collision>
    </link>
    <joint name="front_left_knee_joint" type="revolute">
        <parent link="front_left_hip_link" />
        <child link="front_left_knee_link" />
        <origin xyz="0 0.02 -0.2" rpy="0 0 0" />
        <axis xyz="0 1 0" />
        <limit effort="1.0" velocity="1.0" lower="-3.14" upper="3.14" />
    </joint>

    <!-- Front Right Leg - 동일한 수정 적용 -->
    <link name="front_right_abad_link">
        <inertial>
            <origin xyz="0 0 0" />
            <mass value="0.5" />
            <inertia ixx="0.02" ixy="0" ixz="0" iyy="0.02" iyz="0" izz="0.01" />
        </inertial>
        <visual>
            <origin xyz="0 0 0" rpy="1.5708 0 1.5708" />
            <geometry>
                <cylinder length="0.05" radius="0.02" />
            </geometry>
            <material name="yellow">
                <color rgba="1 1 0 1" />
            </material>
        </visual>
    </link>
    <joint name="front_right_abad_joint" type="revolute">
        <parent link="base_link" />
        <child link="front_right_abad_link" />
        <origin xyz="0.15 -0.1 0" rpy="0 0 0" />
        <axis xyz="1 0 0" />
        <limit effort="1.0" velocity="1.0" lower="-1.5" upper="1.5" />
    </joint>
    <link name="front_right_hip_link">
        <inertial>
            <origin xyz="0 0 -0.1" />
            <mass value="0.7" />
            <inertia ixx="0.03" ixy="0" ixz="0" iyy="0.03" iyz="0" izz="0.02" />
        </inertial>
        <visual>
            <origin xyz="0 -0.02 -0.1" rpy="0 0 0" />
            <geometry>
                <cylinder length="0.2" radius="0.03" />
            </geometry>
            <material name="green">
                <color rgba="0 1 0 1" />
            </material>
        </visual>
        <collision>
            <origin xyz="0 -0.02 -0.1" rpy="0 0 0" />
            <geometry>
                <cylinder length="0.2" radius="0.03" />
            </geometry>
        </collision>
    </link>
    <joint name="front_right_hip_joint" type="revolute">
        <parent link="front_right_abad_link" />
        <child link="front_right_hip_link" />
        <origin xyz="0 -0.02 0" rpy="0 0 0" />
        <axis xyz="0 1 0" />
        <limit effort="1.0" velocity="1.0" lower="-3.14" upper="3.14" />
    </joint>
    <link name="front_right_knee_link">
        <inertial>
            <origin xyz="0 0 -0.1" />
            <mass value="0.4" />
            <inertia ixx="0.02" ixy="0" ixz="0" iyy="0.02" iyz="0" izz="0.01" />
        </inertial>
        <visual>
            <origin xyz="0 -0.02 -0.1" rpy="0 0 0" />
            <geometry>
                <cylinder length="0.2" radius="0.03" />
            </geometry>
            <material name="red">
                <color rgba="1 0 0 1" />
            </material>
        </visual>
        <collision>
            <origin xyz="0 -0.02 -0.1" rpy="0 0 0" />
            <geometry>
                <cylinder length="0.2" radius="0.03" />
            </geometry>
        </collision>
    </link>
    <joint name="front_right_knee_joint" type="revolute">
        <parent link="front_right_hip_link" />
        <child link="front_right_knee_link" />
        <origin xyz="0 -0.02 -0.2" rpy="0 0 0" />
        <axis xyz="0 1 0" />
        <limit effort="1.0" velocity="1.0" lower="-3.14" upper="3.14" />
    </joint>

    <!-- Back Left Leg - 동일한 수정 적용 -->
    <link name="back_left_abad_link">
        <inertial>
            <origin xyz="0 0 0" />
            <mass value="0.5" />
            <inertia ixx="0.02" ixy="0" ixz="0" iyy="0.02" iyz="0" izz="0.01" />
        </inertial>
        <visual>
            <origin xyz="0 0 0" rpy="1.5708 0 1.5708" />
            <geometry>
                <cylinder length="0.05" radius="0.02" />
            </geometry>
            <material name="yellow">
                <color rgba="1 1 0 1" />
            </material>
        </visual>
    </link>
    <joint name="back_left_abad_joint" type="revolute">
        <parent link="base_link" />
        <child link="back_left_abad_link" />
        <origin xyz="-0.13 0.1 0" rpy="0 0 0" />
        <axis xyz="1 0 0" />
        <limit effort="1.0" velocity="1.0" lower="-1.5" upper="1.5" />
    </joint>
    <link name="back_left_hip_link">
        <inertial>
            <origin xyz="0 0 -0.1" />
            <mass value="0.7" />
            <inertia ixx="0.03" ixy="0" ixz="0" iyy="0.03" iyz="0" izz="0.02" />
        </inertial>
        <visual>
            <origin xyz="0 0.02 -0.1" rpy="0 0 0" />
            <geometry>
                <cylinder length="0.2" radius="0.03" />
            </geometry>
            <material name="green">
                <color rgba="0 1 0 1" />
            </material>
        </visual>
        <collision>
            <origin xyz="0 0.02 -0.1" rpy="0 0 0" />
            <geometry>
                <cylinder length="0.2" radius="0.03" />
            </geometry>
        </collision>
    </link>
    <joint name="back_left_hip_joint" type="revolute">
        <parent link="back_left_abad_link" />
        <child link="back_left_hip_link" />
        <origin xyz="0 0.02 0" rpy="0 0 0" />
        <axis xyz="0 1 0" />
        <limit effort="1.0" velocity="1.0" lower="-3.14" upper="3.14" />
    </joint>
    <link name="back_left_knee_link">
        <inertial>
            <origin xyz="0 0 -0.1" />
            <mass value="0.4" />
            <inertia ixx="0.02" ixy="0" ixz="0" iyy="0.02" iyz="0" izz="0.01" />
        </inertial>
        <visual>
            <origin xyz="0 0.02 -0.1" rpy="0 0 0" />
            <geometry>
                <cylinder length="0.2" radius="0.03" />
            </geometry>
            <material name="red">
                <color rgba="1 0 0 1" />
            </material>
        </visual>
        <collision>
            <origin xyz="0 0.02 -0.1" rpy="0 0 0" />
            <geometry>
                <cylinder length="0.2" radius="0.03" />
            </geometry>
        </collision>
    </link>
    <joint name="back_left_knee_joint" type="revolute">
        <parent link="back_left_hip_link" />
        <child link="back_left_knee_link" />
        <origin xyz="0 0.02 -0.2" rpy="0 0 0" />
        <axis xyz="0 1 0" />
        <limit effort="1.0" velocity="1.0" lower="-3.14" upper="3.14" />
    </joint>

    <!-- Back Right Leg - 동일한 수정 적용 -->
    <link name="back_right_abad_link">
        <inertial>
            <origin xyz="0 0 0" />
            <mass value="0.5" />
            <inertia ixx="0.02" ixy="0" ixz="0" iyy="0.02" iyz="0" izz="0.01" />
        </inertial>
        <visual>
            <origin xyz="0 0 0" rpy="1.5708 0 1.5708" />
            <geometry>
                <cylinder length="0.05" radius="0.02" />
            </geometry>
            <material name="yellow">
                <color rgba="1 1 0 1" />
            </material>
        </visual>
    </link>
    <joint name="back_right_abad_joint" type="revolute">
        <parent link="base_link" />
        <child link="back_right_abad_link" />
        <origin xyz="-0.13 -0.1 0" rpy="0 0 0" />
        <axis xyz="1 0 0" />
        <limit effort="1.0" velocity="1.0" lower="-1.5" upper="1.5" />
    </joint>
    <link name="back_right_hip_link">
        <inertial>
            <origin xyz="0 0 -0.1" />
            <mass value="0.7" />
            <inertia ixx="0.03" ixy="0" ixz="0" iyy="0.03" iyz="0" izz="0.02" />
        </inertial>
        <visual>
            <origin xyz="0 -0.02 -0.1" rpy="0 0 0" />
            <geometry>
                <cylinder length="0.2" radius="0.03" />
            </geometry>
            <material name="green">
                <color rgba="0 1 0 1" />
            </material>
        </visual>
        <collision>
            <origin xyz="0 -0.02 -0.1" rpy="0 0 0" />
            <geometry>
                <cylinder length="0.2" radius="0.03" />
            </geometry>
        </collision>
    </link>
    <joint name="back_right_hip_joint" type="revolute">
        <parent link="back_right_abad_link" />
        <child link="back_right_hip_link" />
        <origin xyz="0 -0.02 0" rpy="0 0 0" />
        <axis xyz="0 1 0" />
        <limit effort="1.0" velocity="1.0" lower="-3.14" upper="3.14" />
    </joint>
    <link name="back_right_knee_link">
        <inertial>
            <origin xyz="0 0 -0.1" />
            <mass value="0.4" />
            <inertia ixx="0.02" ixy="0" ixz="0" iyy="0.02" iyz="0" izz="0.01" />
        </inertial>
        <visual>
            <origin xyz="0 -0.02 -0.1" rpy="0 0 0" />
            <geometry>
                <cylinder length="0.2" radius="0.03" />
            </geometry>
            <material name="red">
                <color rgba="1 0 0 1" />
            </material>
        </visual>
        <collision>
            <origin xyz="0 -0.02 -0.1" rpy="0 0 0" />
            <geometry>
                <cylinder length="0.2" radius="0.03" />
            </geometry>
        </collision>
    </link>
    <joint name="back_right_knee_joint" type="revolute">
        <parent link="back_right_hip_link" />
        <child link="back_right_knee_link" />
        <origin xyz="0 -0.02 -0.2" rpy="0 0 0" />
        <axis xyz="0 1 0" />
        <limit effort="1.0" velocity="1.0" lower="-3.14" upper="3.14" />
    </joint>

</robot>
